<?xml version="1.0" encoding="utf-8"?><testsuites><testsuite name="pytest" errors="0" failures="1" skipped="0" tests="1" time="16.750" timestamp="2025-04-01T06:07:25.654403-04:00" hostname="Omars-Mac-Studio.local"><testcase classname="tests.unit.app.test_dependencies" name="test_get_current_user_valid_token" time="13.462"><failure message="AssertionError: expected call not found.&#10;Expected: decode('valid_token', 'SECRET_KEY', algorithms=['HS256'])&#10;  Actual: decode('valid_token', 'ba4732dca5a0eff15d31ae0026b291fcf481afee13a93594410c76f7b26bdcde', algorithms=['HS256'])&#10;&#10;pytest introspection follows:&#10;&#10;Args:&#10;assert ('valid_token', 'ba4732dca5a0eff15d31ae0026b291fcf481afee13a93594410c76f7b26bdcde') == ('valid_token', 'SECRET_KEY')&#10;  &#10;  At index 1 diff: 'ba4732dca5a0eff15d31ae0026b291fcf481afee13a93594410c76f7b26bdcde' != 'SECRET_KEY'&#10;  &#10;  Full diff:&#10;    (&#10;        'valid_token',&#10;  -     'SECRET_KEY',&#10;  +     'ba4732dca5a0eff15d31ae0026b291fcf481afee13a93594410c76f7b26bdcde',&#10;    )">/opt/homebrew/Cellar/python@3.13/3.13.2/Frameworks/Python.framework/Versions/3.13/lib/python3.13/unittest/mock.py:977: in assert_called_with
    raise AssertionError(_error_message()) from cause
E   AssertionError: expected call not found.
E   Expected: decode('valid_token', 'SECRET_KEY', algorithms=['HS256'])
E     Actual: decode('valid_token', 'ba4732dca5a0eff15d31ae0026b291fcf481afee13a93594410c76f7b26bdcde', algorithms=['HS256'])

During handling of the above exception, another exception occurred:
/opt/homebrew/Cellar/python@3.13/3.13.2/Frameworks/Python.framework/Versions/3.13/lib/python3.13/unittest/mock.py:989: in assert_called_once_with
    return self.assert_called_with(*args, **kwargs)
E   AssertionError: expected call not found.
E   Expected: decode('valid_token', 'SECRET_KEY', algorithms=['HS256'])
E     Actual: decode('valid_token', 'ba4732dca5a0eff15d31ae0026b291fcf481afee13a93594410c76f7b26bdcde', algorithms=['HS256'])
E   
E   pytest introspection follows:
E   
E   Args:
E   assert ('valid_token', 'ba4732dca5a0eff15d31ae0026b291fcf481afee13a93594410c76f7b26bdcde') == ('valid_token', 'SECRET_KEY')
E     
E     At index 1 diff: 'ba4732dca5a0eff15d31ae0026b291fcf481afee13a93594410c76f7b26bdcde' != 'SECRET_KEY'
E     
E     Full diff:
E       (
E           'valid_token',
E     -     'SECRET_KEY',
E     +     'ba4732dca5a0eff15d31ae0026b291fcf481afee13a93594410c76f7b26bdcde',
E       )

During handling of the above exception, another exception occurred:
app/test_dependencies.py:73: in test_get_current_user_valid_token
    mock_jwt.decode.assert_called_once_with(token, "SECRET_KEY", algorithms=["HS256"])
E   AssertionError: expected call not found.
E   Expected: decode('valid_token', 'SECRET_KEY', algorithms=['HS256'])
E     Actual: decode('valid_token', 'ba4732dca5a0eff15d31ae0026b291fcf481afee13a93594410c76f7b26bdcde', algorithms=['HS256'])
E   
E   pytest introspection follows:
E   
E   Args:
E   assert ('valid_token', 'ba4732dca5a0eff15d31ae0026b291fcf481afee13a93594410c76f7b26bdcde') == ('valid_token', 'SECRET_KEY')
E     
E     At index 1 diff: 'ba4732dca5a0eff15d31ae0026b291fcf481afee13a93594410c76f7b26bdcde' != 'SECRET_KEY'
E     
E     Full diff:
E       (
E           'valid_token',
E     -     'SECRET_KEY',
E     +     'ba4732dca5a0eff15d31ae0026b291fcf481afee13a93594410c76f7b26bdcde',
E       )</failure></testcase></testsuite></testsuites>