<?xml version="1.0" encoding="utf-8"?><testsuites><testsuite name="pytest" errors="0" failures="1" skipped="0" tests="1" time="29.899" timestamp="2025-03-30T14:29:06.457303-04:00" hostname="Omars-Mac-Studio.local"><testcase classname="tests.unit.app.test_dependencies" name="test_get_current_user_valid_token" time="23.599"><failure message="sqlalchemy.exc.OperationalError: (sqlite3.OperationalError) no such table: users&#10;[SQL: SELECT users.id, users.username, users.email, users.full_name, users.disabled, users.hashed_password &#10;FROM users &#10;WHERE users.username = ?]&#10;[parameters: ('testuser',)]&#10;(Background on this error at: https://sqlalche.me/e/20/e3q8)">../../.venv/lib/python3.13/site-packages/sqlalchemy/engine/base.py:1964: in _exec_single_context
    self.dialect.do_execute(
../../.venv/lib/python3.13/site-packages/sqlalchemy/engine/default.py:942: in do_execute
    cursor.execute(statement, parameters)
E   sqlite3.OperationalError: no such table: users

The above exception was the direct cause of the following exception:
app/test_dependencies.py:58: in test_get_current_user_valid_token
    user = await get_current_user(token="valid_token")
../../app/dependencies.py:49: in get_current_user
    user = service.read_by_username(username=token_data.username)
../../app/services/user.py:45: in read_by_username
    return self.repo.read_by_username(username)
../../app/repositories/user.py:43: in read_by_username
    user = session.exec(statement).first()
../../.venv/lib/python3.13/site-packages/sqlmodel/orm/session.py:66: in exec
    results = super().execute(
../../.venv/lib/python3.13/site-packages/sqlalchemy/orm/session.py:2365: in execute
    return self._execute_internal(
../../.venv/lib/python3.13/site-packages/sqlalchemy/orm/session.py:2251: in _execute_internal
    result: Result[Any] = compile_state_cls.orm_execute_statement(
../../.venv/lib/python3.13/site-packages/sqlalchemy/orm/context.py:306: in orm_execute_statement
    result = conn.execute(
../../.venv/lib/python3.13/site-packages/sqlalchemy/engine/base.py:1416: in execute
    return meth(
../../.venv/lib/python3.13/site-packages/sqlalchemy/sql/elements.py:523: in _execute_on_connection
    return connection._execute_clauseelement(
../../.venv/lib/python3.13/site-packages/sqlalchemy/engine/base.py:1638: in _execute_clauseelement
    ret = self._execute_context(
../../.venv/lib/python3.13/site-packages/sqlalchemy/engine/base.py:1843: in _execute_context
    return self._exec_single_context(
../../.venv/lib/python3.13/site-packages/sqlalchemy/engine/base.py:1983: in _exec_single_context
    self._handle_dbapi_exception(
../../.venv/lib/python3.13/site-packages/sqlalchemy/engine/base.py:2352: in _handle_dbapi_exception
    raise sqlalchemy_exception.with_traceback(exc_info[2]) from e
../../.venv/lib/python3.13/site-packages/sqlalchemy/engine/base.py:1964: in _exec_single_context
    self.dialect.do_execute(
../../.venv/lib/python3.13/site-packages/sqlalchemy/engine/default.py:942: in do_execute
    cursor.execute(statement, parameters)
E   sqlalchemy.exc.OperationalError: (sqlite3.OperationalError) no such table: users
E   [SQL: SELECT users.id, users.username, users.email, users.full_name, users.disabled, users.hashed_password 
E   FROM users 
E   WHERE users.username = ?]
E   [parameters: ('testuser',)]
E   (Background on this error at: https://sqlalche.me/e/20/e3q8)</failure></testcase></testsuite></testsuites>